Workbook
Name _Toc209096171: [1]QoS_Test_Results!$A$5

Sheet Summary
A1: Firmware Version | B1: 4.0.3 | C1: Detailed Statistics by Object
A2: Module | B2: Object Category | C2: Total Items | D2: Tested Items | E2: Pass | F2: Fail | G2: To be confirmed | H2: Not Supported | I2: Skip | J2: Pass Rate | K2: result empty | L2: Progress
A3: WiFi 5g | B3: WiFi.AccessPoint | C3: =COUNTIF(Wifi_LLAPI!$A:$A,$B3&"*") | D3: =SUM(E3:I3) | E3: =COUNTIFS(Wifi_LLAPI!$A:$A,$B3&"*",Wifi_LLAPI!$N:$N,E$2) | F3: =COUNTIFS(Wifi_LLAPI!$A:$A,$B3&"*",Wifi_LLAPI!$N:$N,F$2) | G3: =COUNTIFS(Wifi_LLAPI!$A:$A,$B3&"*",Wifi_LLAPI!$N:$N,G$2) | H3: =COUNTIFS(Wifi_LLAPI!$A:$A,$B3&"*",Wifi_LLAPI!$N:$N,H$2)+COUNTIFS(Wifi_LLAPI!$A:$A,$B3&"*",Wifi_LLAPI!$E:$E,"Not Supported",Wifi_LLAPI!$N:$N,"") | I3: =COUNTIFS(Wifi_LLAPI!$A:$A,$B3&"*",Wifi_LLAPI!$N:$N,I$2)+COUNTIFS(Wifi_LLAPI!$A:$A,$B3&"*",Wifi_LLAPI!$N:$N,"N/A") | J3: =IFERROR(E3/SUM(E3:F3),0) | K3: =MAX(C3-D3,0) | L3: =IFERROR(D3/C3,0) | N3: Module | O3: Finish % | P3: Automation %
B4: WiFi.EndPoint | C4: =COUNTIF(Wifi_LLAPI!$A:$A,$B4&"*") | D4: =SUM(E4:I4) | E4: =COUNTIFS(Wifi_LLAPI!$A:$A,$B4&"*",Wifi_LLAPI!$N:$N,E$2) | F4: =COUNTIFS(Wifi_LLAPI!$A:$A,$B4&"*",Wifi_LLAPI!$N:$N,F$2) | G4: =COUNTIFS(Wifi_LLAPI!$A:$A,$B4&"*",Wifi_LLAPI!$N:$N,G$2) | H4: =COUNTIFS(Wifi_LLAPI!$A:$A,$B4&"*",Wifi_LLAPI!$N:$N,H$2)+COUNTIFS(Wifi_LLAPI!$A:$A,$B4&"*",Wifi_LLAPI!$E:$E,"Not Supported",Wifi_LLAPI!$N:$N,"") | I4: =COUNTIFS(Wifi_LLAPI!$A:$A,$B4&"*",Wifi_LLAPI!$N:$N,I$2)+COUNTIFS(Wifi_LLAPI!$A:$A,$B4&"*",Wifi_LLAPI!$N:$N,"N/A") | J4: =IFERROR(E4/SUM(E4:F4),0) | K4: =MAX(C4-D4,0) | L4: =IFERROR(D4/C4,0) | N4: =A3 | O4: =L8 | P4: =IFERROR(SUM(E8:G8)/C8,0)
B5: WiFi.Radio | C5: =COUNTIF(Wifi_LLAPI!$A:$A,$B5&"*") | D5: =SUM(E5:I5) | E5: =COUNTIFS(Wifi_LLAPI!$A:$A,$B5&"*",Wifi_LLAPI!$N:$N,E$2) | F5: =COUNTIFS(Wifi_LLAPI!$A:$A,$B5&"*",Wifi_LLAPI!$N:$N,F$2) | G5: =COUNTIFS(Wifi_LLAPI!$A:$A,$B5&"*",Wifi_LLAPI!$N:$N,G$2) | H5: =COUNTIFS(Wifi_LLAPI!$A:$A,$B5&"*",Wifi_LLAPI!$N:$N,H$2)+COUNTIFS(Wifi_LLAPI!$A:$A,$B5&"*",Wifi_LLAPI!$E:$E,"Not Supported",Wifi_LLAPI!$N:$N,"") | I5: =COUNTIFS(Wifi_LLAPI!$A:$A,$B5&"*",Wifi_LLAPI!$N:$N,I$2)+COUNTIFS(Wifi_LLAPI!$A:$A,$B5&"*",Wifi_LLAPI!$N:$N,"N/A") | J5: =IFERROR(E5/SUM(E5:F5),0) | K5: =MAX(C5-D5,0) | L5: =IFERROR(D5/C5,0) | N5: =A9 | O5: =L14 | P5: =IFERROR(SUM(E14:G14)/C14,0)
B6: WiFi.SSID | C6: =COUNTIF(Wifi_LLAPI!$A:$A,$B6&"*") | D6: =SUM(E6:I6) | E6: =COUNTIFS(Wifi_LLAPI!$A:$A,$B6&"*",Wifi_LLAPI!$N:$N,E$2) | F6: =COUNTIFS(Wifi_LLAPI!$A:$A,$B6&"*",Wifi_LLAPI!$N:$N,F$2) | G6: =COUNTIFS(Wifi_LLAPI!$A:$A,$B6&"*",Wifi_LLAPI!$N:$N,G$2) | H6: =COUNTIFS(Wifi_LLAPI!$A:$A,$B6&"*",Wifi_LLAPI!$N:$N,H$2)+COUNTIFS(Wifi_LLAPI!$A:$A,$B6&"*",Wifi_LLAPI!$E:$E,"Not Supported",Wifi_LLAPI!$N:$N,"") | I6: =COUNTIFS(Wifi_LLAPI!$A:$A,$B6&"*",Wifi_LLAPI!$N:$N,I$2)+COUNTIFS(Wifi_LLAPI!$A:$A,$B6&"*",Wifi_LLAPI!$N:$N,"N/A") | J6: =IFERROR(E6/SUM(E6:F6),0) | K6: =MAX(C6-D6,0) | L6: =IFERROR(D6/C6,0) | N6: =A15 | O6: =L20 | P6: =IFERROR(SUM(E20:G20)/C20,0)
B7: WiFi.wps_DefParam | C7: =COUNTIF(Wifi_LLAPI!$A:$A,$B7&"*") | D7: =SUM(E7:I7) | E7: =COUNTIFS(Wifi_LLAPI!$A:$A,$B7&"*",Wifi_LLAPI!$N:$N,E$2) | F7: =COUNTIFS(Wifi_LLAPI!$A:$A,$B7&"*",Wifi_LLAPI!$N:$N,F$2) | G7: =COUNTIFS(Wifi_LLAPI!$A:$A,$B7&"*",Wifi_LLAPI!$N:$N,G$2) | H7: =COUNTIFS(Wifi_LLAPI!$A:$A,$B7&"*",Wifi_LLAPI!$N:$N,H$2)+COUNTIFS(Wifi_LLAPI!$A:$A,$B7&"*",Wifi_LLAPI!$E:$E,"Not Supported",Wifi_LLAPI!$N:$N,"") | I7: =COUNTIFS(Wifi_LLAPI!$A:$A,$B7&"*",Wifi_LLAPI!$N:$N,I$2)+COUNTIFS(Wifi_LLAPI!$A:$A,$B7&"*",Wifi_LLAPI!$N:$N,"N/A") | J7: =IFERROR(E7/SUM(E7:F7),0) | K7: =MAX(C7-D7,0) | L7: =IFERROR(D7/C7,0)
B8: TOTAL | C8: =SUM(C3:C7) | D8: =SUM(D3:D7) | E8: =SUM(E3:E7) | F8: =SUM(F3:F7) | G8: =SUM(G3:G7) | H8: =SUM(H3:H7) | I8: =SUM(I3:I7) | J8: =IFERROR(E8/SUM(E8:F8),0) | K8: =SUM(K3:K7) | L8: =IFERROR(D8/C8,0)
A9: WiFi 6g | B9: WiFi.AccessPoint | C9: =COUNTIF(Wifi_LLAPI!$A:$A,$B9&"*") | D9: =SUM(E9:I9) | E9: =COUNTIFS(Wifi_LLAPI!$A:$A,$B9&"*",Wifi_LLAPI!$O:$O,E$2) | F9: =COUNTIFS(Wifi_LLAPI!$A:$A,$B9&"*",Wifi_LLAPI!$O:$O,F$2) | G9: =COUNTIFS(Wifi_LLAPI!$A:$A,$B9&"*",Wifi_LLAPI!$O:$O,G$2) | H9: =COUNTIFS(Wifi_LLAPI!$A:$A,$B9&"*",Wifi_LLAPI!$O:$O,H$2)+COUNTIFS(Wifi_LLAPI!$A:$A,$B9&"*",Wifi_LLAPI!$E:$E,"Not Supported",Wifi_LLAPI!$O:$O,"") | I9: =COUNTIFS(Wifi_LLAPI!$A:$A,$B9&"*",Wifi_LLAPI!$O:$O,I$2)+COUNTIFS(Wifi_LLAPI!$A:$A,$B9&"*",Wifi_LLAPI!$O:$O,"N/A") | J9: =IFERROR(E9/SUM(E9:F9),0) | K9: =MAX(C9-D9,0) | L9: =IFERROR(D9/C9,0)
B10: WiFi.EndPoint | C10: =COUNTIF(Wifi_LLAPI!$A:$A,$B10&"*") | D10: =SUM(E10:I10) | E10: =COUNTIFS(Wifi_LLAPI!$A:$A,$B10&"*",Wifi_LLAPI!$O:$O,E$2) | F10: =COUNTIFS(Wifi_LLAPI!$A:$A,$B10&"*",Wifi_LLAPI!$O:$O,F$2) | G10: =COUNTIFS(Wifi_LLAPI!$A:$A,$B10&"*",Wifi_LLAPI!$O:$O,G$2) | H10: =COUNTIFS(Wifi_LLAPI!$A:$A,$B10&"*",Wifi_LLAPI!$O:$O,H$2)+COUNTIFS(Wifi_LLAPI!$A:$A,$B10&"*",Wifi_LLAPI!$E:$E,"Not Supported",Wifi_LLAPI!$O:$O,"") | I10: =COUNTIFS(Wifi_LLAPI!$A:$A,$B10&"*",Wifi_LLAPI!$O:$O,I$2)+COUNTIFS(Wifi_LLAPI!$A:$A,$B10&"*",Wifi_LLAPI!$O:$O,"N/A") | J10: =IFERROR(E10/SUM(E10:F10),0) | K10: =MAX(C10-D10,0) | L10: =IFERROR(D10/C10,0)
B11: WiFi.Radio | C11: =COUNTIF(Wifi_LLAPI!$A:$A,$B11&"*") | D11: =SUM(E11:I11) | E11: =COUNTIFS(Wifi_LLAPI!$A:$A,$B11&"*",Wifi_LLAPI!$O:$O,E$2) | F11: =COUNTIFS(Wifi_LLAPI!$A:$A,$B11&"*",Wifi_LLAPI!$O:$O,F$2) | G11: =COUNTIFS(Wifi_LLAPI!$A:$A,$B11&"*",Wifi_LLAPI!$O:$O,G$2) | H11: =COUNTIFS(Wifi_LLAPI!$A:$A,$B11&"*",Wifi_LLAPI!$O:$O,H$2)+COUNTIFS(Wifi_LLAPI!$A:$A,$B11&"*",Wifi_LLAPI!$E:$E,"Not Supported",Wifi_LLAPI!$O:$O,"") | I11: =COUNTIFS(Wifi_LLAPI!$A:$A,$B11&"*",Wifi_LLAPI!$O:$O,I$2)+COUNTIFS(Wifi_LLAPI!$A:$A,$B11&"*",Wifi_LLAPI!$O:$O,"N/A") | J11: =IFERROR(E11/SUM(E11:F11),0) | K11: =MAX(C11-D11,0) | L11: =IFERROR(D11/C11,0)
B12: WiFi.SSID | C12: =COUNTIF(Wifi_LLAPI!$A:$A,$B12&"*") | D12: =SUM(E12:I12) | E12: =COUNTIFS(Wifi_LLAPI!$A:$A,$B12&"*",Wifi_LLAPI!$O:$O,E$2) | F12: =COUNTIFS(Wifi_LLAPI!$A:$A,$B12&"*",Wifi_LLAPI!$O:$O,F$2) | G12: =COUNTIFS(Wifi_LLAPI!$A:$A,$B12&"*",Wifi_LLAPI!$O:$O,G$2) | H12: =COUNTIFS(Wifi_LLAPI!$A:$A,$B12&"*",Wifi_LLAPI!$O:$O,H$2)+COUNTIFS(Wifi_LLAPI!$A:$A,$B12&"*",Wifi_LLAPI!$E:$E,"Not Supported",Wifi_LLAPI!$O:$O,"") | I12: =COUNTIFS(Wifi_LLAPI!$A:$A,$B12&"*",Wifi_LLAPI!$O:$O,I$2)+COUNTIFS(Wifi_LLAPI!$A:$A,$B12&"*",Wifi_LLAPI!$O:$O,"N/A") | J12: =IFERROR(E12/SUM(E12:F12),0) | K12: =MAX(C12-D12,0) | L12: =IFERROR(D12/C12,0)
B13: WiFi.wps_DefParam | C13: =COUNTIF(Wifi_LLAPI!$A:$A,$B13&"*") | D13: =SUM(E13:I13) | E13: =COUNTIFS(Wifi_LLAPI!$A:$A,$B13&"*",Wifi_LLAPI!$O:$O,E$2) | F13: =COUNTIFS(Wifi_LLAPI!$A:$A,$B13&"*",Wifi_LLAPI!$O:$O,F$2) | G13: =COUNTIFS(Wifi_LLAPI!$A:$A,$B13&"*",Wifi_LLAPI!$O:$O,G$2) | H13: =COUNTIFS(Wifi_LLAPI!$A:$A,$B13&"*",Wifi_LLAPI!$O:$O,H$2)+COUNTIFS(Wifi_LLAPI!$A:$A,$B13&"*",Wifi_LLAPI!$E:$E,"Not Supported",Wifi_LLAPI!$O:$O,"") | I13: =COUNTIFS(Wifi_LLAPI!$A:$A,$B13&"*",Wifi_LLAPI!$O:$O,I$2)+COUNTIFS(Wifi_LLAPI!$A:$A,$B13&"*",Wifi_LLAPI!$O:$O,"N/A") | J13: =IFERROR(E13/SUM(E13:F13),0) | K13: =MAX(C13-D13,0) | L13: =IFERROR(D13/C13,0)
B14: TOTAL | C14: =SUM(C9:C13) | D14: =SUM(D9:D13) | E14: =SUM(E9:E13) | F14: =SUM(F9:F13) | G14: =SUM(G9:G13) | H14: =SUM(H9:H13) | I14: =SUM(I9:I13) | J14: =IFERROR(E14/SUM(E14:F14),0) | K14: =SUM(K9:K13) | L14: =IFERROR(D14/C14,0)
A15: WiFi 2.4g | B15: WiFi.AccessPoint | C15: =COUNTIF(Wifi_LLAPI!$A:$A,$B15&"*") | D15: =SUM(E15:I15) | E15: =COUNTIFS(Wifi_LLAPI!$A:$A,$B15&"*",Wifi_LLAPI!$P:$P,E$2) | F15: =COUNTIFS(Wifi_LLAPI!$A:$A,$B15&"*",Wifi_LLAPI!$P:$P,F$2) | G15: =COUNTIFS(Wifi_LLAPI!$A:$A,$B15&"*",Wifi_LLAPI!$P:$P,G$2) | H15: =COUNTIFS(Wifi_LLAPI!$A:$A,$B15&"*",Wifi_LLAPI!$P:$P,H$2)+COUNTIFS(Wifi_LLAPI!$A:$A,$B15&"*",Wifi_LLAPI!$E:$E,"Not Supported",Wifi_LLAPI!$P:$P,"") | I15: =COUNTIFS(Wifi_LLAPI!$A:$A,$B15&"*",Wifi_LLAPI!$P:$P,I$2)+COUNTIFS(Wifi_LLAPI!$A:$A,$B15&"*",Wifi_LLAPI!$P:$P,"N/A") | J15: =IFERROR(E15/SUM(E15:F15),0) | K15: =MAX(C15-D15,0) | L15: =IFERROR(D15/C15,0)
B16: WiFi.EndPoint | C16: =COUNTIF(Wifi_LLAPI!$A:$A,$B16&"*") | D16: =SUM(E16:I16) | E16: =COUNTIFS(Wifi_LLAPI!$A:$A,$B16&"*",Wifi_LLAPI!$P:$P,E$2) | F16: =COUNTIFS(Wifi_LLAPI!$A:$A,$B16&"*",Wifi_LLAPI!$P:$P,F$2) | G16: =COUNTIFS(Wifi_LLAPI!$A:$A,$B16&"*",Wifi_LLAPI!$P:$P,G$2) | H16: =COUNTIFS(Wifi_LLAPI!$A:$A,$B16&"*",Wifi_LLAPI!$P:$P,H$2)+COUNTIFS(Wifi_LLAPI!$A:$A,$B16&"*",Wifi_LLAPI!$E:$E,"Not Supported",Wifi_LLAPI!$P:$P,"") | I16: =COUNTIFS(Wifi_LLAPI!$A:$A,$B16&"*",Wifi_LLAPI!$P:$P,I$2)+COUNTIFS(Wifi_LLAPI!$A:$A,$B16&"*",Wifi_LLAPI!$P:$P,"N/A") | J16: =IFERROR(E16/SUM(E16:F16),0) | K16: =MAX(C16-D16,0) | L16: =IFERROR(D16/C16,0)
B17: WiFi.Radio | C17: =COUNTIF(Wifi_LLAPI!$A:$A,$B17&"*") | D17: =SUM(E17:I17) | E17: =COUNTIFS(Wifi_LLAPI!$A:$A,$B17&"*",Wifi_LLAPI!$P:$P,E$2) | F17: =COUNTIFS(Wifi_LLAPI!$A:$A,$B17&"*",Wifi_LLAPI!$P:$P,F$2) | G17: =COUNTIFS(Wifi_LLAPI!$A:$A,$B17&"*",Wifi_LLAPI!$P:$P,G$2) | H17: =COUNTIFS(Wifi_LLAPI!$A:$A,$B17&"*",Wifi_LLAPI!$P:$P,H$2)+COUNTIFS(Wifi_LLAPI!$A:$A,$B17&"*",Wifi_LLAPI!$E:$E,"Not Supported",Wifi_LLAPI!$P:$P,"") | I17: =COUNTIFS(Wifi_LLAPI!$A:$A,$B17&"*",Wifi_LLAPI!$P:$P,I$2)+COUNTIFS(Wifi_LLAPI!$A:$A,$B17&"*",Wifi_LLAPI!$P:$P,"N/A") | J17: =IFERROR(E17/SUM(E17:F17),0) | K17: =MAX(C17-D17,0) | L17: =IFERROR(D17/C17,0)
B18: WiFi.SSID | C18: =COUNTIF(Wifi_LLAPI!$A:$A,$B18&"*") | D18: =SUM(E18:I18) | E18: =COUNTIFS(Wifi_LLAPI!$A:$A,$B18&"*",Wifi_LLAPI!$P:$P,E$2) | F18: =COUNTIFS(Wifi_LLAPI!$A:$A,$B18&"*",Wifi_LLAPI!$P:$P,F$2) | G18: =COUNTIFS(Wifi_LLAPI!$A:$A,$B18&"*",Wifi_LLAPI!$P:$P,G$2) | H18: =COUNTIFS(Wifi_LLAPI!$A:$A,$B18&"*",Wifi_LLAPI!$P:$P,H$2)+COUNTIFS(Wifi_LLAPI!$A:$A,$B18&"*",Wifi_LLAPI!$E:$E,"Not Supported",Wifi_LLAPI!$P:$P,"") | I18: =COUNTIFS(Wifi_LLAPI!$A:$A,$B18&"*",Wifi_LLAPI!$P:$P,I$2)+COUNTIFS(Wifi_LLAPI!$A:$A,$B18&"*",Wifi_LLAPI!$P:$P,"N/A") | J18: =IFERROR(E18/SUM(E18:F18),0) | K18: =MAX(C18-D18,0) | L18: =IFERROR(D18/C18,0)
B19: WiFi.wps_DefParam | C19: =COUNTIF(Wifi_LLAPI!$A:$A,$B19&"*") | D19: =SUM(E19:I19) | E19: =COUNTIFS(Wifi_LLAPI!$A:$A,$B19&"*",Wifi_LLAPI!$P:$P,E$2) | F19: =COUNTIFS(Wifi_LLAPI!$A:$A,$B19&"*",Wifi_LLAPI!$P:$P,F$2) | G19: =COUNTIFS(Wifi_LLAPI!$A:$A,$B19&"*",Wifi_LLAPI!$P:$P,G$2) | H19: =COUNTIFS(Wifi_LLAPI!$A:$A,$B19&"*",Wifi_LLAPI!$P:$P,H$2)+COUNTIFS(Wifi_LLAPI!$A:$A,$B19&"*",Wifi_LLAPI!$E:$E,"Not Supported",Wifi_LLAPI!$P:$P,"") | I19: =COUNTIFS(Wifi_LLAPI!$A:$A,$B19&"*",Wifi_LLAPI!$P:$P,I$2)+COUNTIFS(Wifi_LLAPI!$A:$A,$B19&"*",Wifi_LLAPI!$P:$P,"N/A") | J19: =IFERROR(E19/SUM(E19:F19),0) | K19: =MAX(C19-D19,0) | L19: =IFERROR(D19/C19,0)
B20: TOTAL | C20: =SUM(C15:C19) | D20: =SUM(D15:D19) | E20: =SUM(E15:E19) | F20: =SUM(F15:F19) | G20: =SUM(G15:G19) | H20: =SUM(H15:H19) | I20: =SUM(I15:I19) | J20: =IFERROR(E20/SUM(E20:F20),0) | K20: =SUM(K15:K19) | L20: =IFERROR(D20/C20,0)
B22: Total Items : The total number of test items defined for the object category. The total value include. The value of Total Items is the sum of Pass, Fail, To be confirmed, Not Supported, and Skip items. Pass : Tested and passed Fail : Tested and failed To be confirmed: 1. In the current test environment, no Wi-Fi station is capable of generating intentionally malformed or manipulated IEEE 802.11e error frames. Additionally, Scapy cannot be used for this purpose due to Wi-Fi station and driver limitations. Testing will be revisited once appropriate Wi-Fi protocol test equipment or interference generation capability becomes available. 2. No ethernet RMON test environment Not Supported : 1. Not supported by prplWare’s pWHM 2. Not supported by Wi-Fi standards Skip : This project is a gateway (GW) and does not support WiFi Station Mode. Pass Rate : The percentage of passed test items, calculated as Pass / (Pass + Fail).
B23: Test Environment Information : SFP module : HUMAX: HMXHNXGSPP-MAAMC OLT : ALU 7360 ISAM / Software version: isam-release : R6.5.02a Ethernet (10G) : ASUS XG-C100C 10G PCI-E Network Adapter, driver 2.2.2.0 Ethernet (2.5G) : 8156 Realtek Semiconductor Corp. USB 10/100/1G/2.5G, driver: r8152 version: v1.12.13

Sheet Wifi_LLAPI
A1: Object | B1: Object Type | C1: Parameter Name | D1: HLAPI | E1: LLAPI | F1: Implemented by | G1: Test steps | H1: Command Output Verified via "Driver-level / kernel-level utilities" | I1: ARC 4.0.1 Test Result WiFi 5g | J1: ARC 4.0.1 Test Result WiFi 6g | K1: ARC 4.0.1 Test Result WiFi 2.4g | L1: Tester
A2: WiFi.AccessPoint.{i}. | B2: AccessPoint | C2: cleanStation() | D2: ubus-cli "WiFi.AccessPoint.{i}.cleanStation(macaddress=string):bool" | E2: Not Supported | F2: Not Support
A3: WiFi.AccessPoint.{i}. | B3: AccessPoint | C3: delNeighbourAP() | D3: ubus-cli "WiFi.AccessPoint.{i}.delNeighbourAP(BSSID=string):void" | E3: Not Supported | F3: Not Support | I3: WiFi 5G | J3: WiFi 6G | K3: WiFi 2.4G | L3: Tester | M3: Comment | N3: Summary Bucket WiFi 5G | O3: Summary Bucket WiFi 6G | P3: Summary Bucket WiFi 2.4G
A4: WiFi.AccessPoint.{i}. | B4: AccessPoint | C4: kickStation() | D4: ubus-cli "WiFi.AccessPoint.{i}.kickStation(macaddress=string):bool" | E4: Support | F4: pWHM
A5: WiFi.AccessPoint.{i}. | B5: AccessPoint | C5: kickStationReason() | D5: ubus-cli WiFi.AccessPoint.{i}.kickStationReason(macaddress=string, reason:int):bool | E5: Support | F5: pWHM
A6: WiFi.AccessPoint.{i}. | B6: AccessPoint | C6: sendBssTransferRequest() | D6: ubus-cli WiFi.AccessPoint.{i}.sendBssTransferRequest(mac:string, target:string, class:int, channel:int, wait:int, retries:int, validity:int, disassoc:int, bssidInfo:uint32):bool | E6: Support | F6: pWHM
A7: WiFi.AccessPoint.{i}. | B7: AccessPoint | C7: sendRemoteMeasumentRequest() | D7: ubus-cli WiFi.AccessPoint.{i}.sendRemoteMeasumentRequest(mac:string, bssid:string, class:uint32, channel:uint32, timeout:uint32):bool | E7: Support | F7: pWHM
A8: WiFi.AccessPoint.{i}. | B8: AccessPoint | C8: setNeighbourAP() | D8: ubus-cli WiFi.AccessPoint.{i}.setNeighbourAP(BSSID:string, Information:int32, OperatingClass:int32, Channel:int32, PhyType:int32, NASIdentifier:string, R0KHKey:string):void | E8: Not Supported | F8: Not Support
A9: WiFi.AccessPoint.{i}.AssociatedDevice.{i}. | B9: AssociatedDevice | C9: AssociationTime | D9: ubus-cli WiFi.AccessPoint.{i}.AssociatedDevice.{i}.AssociationTime=2021-06-04T16:05:34Z | E9: Support | F9: pWHM
A10: WiFi.AccessPoint.{i}.AssociatedDevice.{i}. | B10: AssociatedDevice | C10: AuthenticationState | D10: ubus-cli WiFi.AccessPoint.{i}.AssociatedDevice.{i}.AuthenticationState=1 | E10: Support | F10: pWHM
A11: WiFi.AccessPoint.{i}.AssociatedDevice.{i}. | B11: AssociatedDevice | C11: AvgSignalStrength | D11: ubus-cli WiFi.AccessPoint.{i}.AssociatedDevice.{i}.AvgSignalStrength=-37 | E11: Support | F11: pWHM | G11: iw dev wl0 link wpa_cli -p /var/run/wpa_supplicant -i wl0 status wl -i wl0 assoclist | tr 'A-F' 'a-f' | sed -n 's/^assoclist \([^ ]*\).*$/AssocMac5g=\1/p' STA_MAC=$(wl -i wl0 assoclist | awk 'NR==1{print $2}'); [ -n "$STA_MAC" ] && wl -i wl0 sta_info $STA_MAC | sed -n 's/.*smoothed rssi: *\(-*[0-9][0-9]*\).*/DriverSmoothedRSSI5g=\1/p' ubus-cli "WiFi.AccessPoint.1.AssociatedDevice.1.AvgSignalStrength?" iw dev wl1 link wpa_cli -p /var/run/wpa_supplicant -i wl1 status wl -i wl1 status wl -i wl1 assoclist | tr 'A-F' 'a-f' | sed -n 's/^assoclist \([^ ]*\).*$/AssocMac6g=\1/p' STA_MAC=$(wl -i wl1 assoclist | awk 'NR==1{print $2}'); [ -n "$STA_MAC" ] && wl -i wl1 sta_info $STA_MAC | sed -n 's/.*smoothed rssi: *\(-*[0-9][0-9]*\).*/DriverSmoothedRSSI6g=\1/p' ubus-cli "WiFi.AccessPoint.3.AssociatedDevice.1.AvgSignalStrength?" iw dev wl2 link wpa_cli -p /var/run/wpa_supplicant -i wl2 status wl -i wl2 assoclist | tr 'A-F' 'a-f' | sed -n 's/^assoclist \([^ ]*\).*$/AssocMac24g=\1/p' STA_MAC=$(wl -i wl2 assoclist | awk 'NR==1{print $2}'); [ -n "$STA_MAC" ] && wl -i wl2 sta_info $STA_MAC | sed -n 's/.*smoothed rssi: *\(-*[0-9][0-9]*\).*/DriverSmoothedRSSI24g=\1/p' ubus-cli "WiFi.AccessPoint.5.AssociatedDevice.1.AvgSignalStrength?" | H11: Connected to 2c:59:17:00:42:15 (on wl0) SSID: testpilot5G freq: 5180 RX: 448 bytes (2 packets) TX: 0 bytes (10 packets) signal: -42 dBm tx bitrate: 6.0 MBit/s bssid=2c:59:17:00:42:15 freq=5180 ssid=testpilot5G id=0 mode=station wifi_generation=6 pairwise_cipher=CCMP group_cipher=CCMP key_mgmt=SAE pmf=2 mgmt_group_cipher=BIP wpa_state=COMPLETED address=2c:59:17:00:19:95 uuid=e5475359-0e8d-5adc-98d5-65101bfa787e ]*\).*$/AssocMac5g=\1/p' AssocMac5g=2c:59:17:00:19:95 DriverSmoothedRSSI5g=-36 ?" WiFi.AccessPoint.1.AssociatedDevice.1.AvgSignalStrength=0 Connected to 2c:59:17:00:42:16 (on wl1) SSID: testpilot6G freq: 5955 RX: 448 bytes (2 packets) TX: 0 bytes (11 packets) signal: -70 dBm tx bitrate: 541.6 MBit/s bssid=2c:59:17:00:42:16 freq=5955 ssid=testpilot6G id=0 mode=station wifi_generation=6 pairwise_cipher=CCMP group_cipher=CCMP key_mgmt=SAE pmf=2 mgmt_group_cipher=BIP wpa_state=COMPLETED address=2c:59:17:00:19:96 uuid=07effc44-4fe4-5920-9b05-3f7dbab41ad0 SSID: "testpilot6G" Mode: Managed RSSI: -66 dBm SNR: 27 dB noise: -94 dBm Flags: FromBcn RSSI on-channel Channel: 6g1 BSSID: 2C:59:17:00:42:16 Capability: ESS WEP RRM Beacon Interval: 100 msecs DTIM Period: 3 Supported Rates: [ 6(b) 9 12 18 24(b) 36 48 54 ] RSN (WPA3-SAE): multicast cipher: AES-CCMP unicast ciphers(1): AES-CCMP AKM Suites(1): SAE Capabilities(0x00cc): No Pre-Auth, Pairwise, 16 PTK Replay Ctrs1 GTK Replay Ctr, MFP: Required Extended Capabilities: IW BSS_Transition HE Capable: Chanspec: 6GHz channel 1 20MHz (0x5001) Primary channel: 1 Negotiated HE MCS: 20/40/80 MHz: NSS1 Tx: 0-11 Rx: 0-11 NSS2 Tx: 0-11 Rx: 0-11 NSS3 Tx: 0-11 Rx: 0-11 NSS4 Tx: 0-11 Rx: 0-11 160 MHz: NSS1 Tx: 0-11 Rx: 0-11 NSS2 Tx: 0-11 Rx: 0-11 NSS3 Tx: 0-11 Rx: 0-11 NSS4 Tx: 0-11 Rx: 0-11 BSS Color: 0x28 Partial BSS Color: false BSS Color Disabled: true VS_IE:dd090010180200001c0000 VS_IE:dd180050f2020101010003a4000027a4000042435e0062322f00 VS_IE:dd07506f9a16010100 QBSS Channel Utilization: 0x10 (6 %) ]*\).*$/AssocMac6g=\1/p' AssocMac6g=2c:59:17:00:19:96 DriverSmoothedRSSI6g=-60 ?" WiFi.AccessPoint.3.AssociatedDevice.1.AvgSignalStrength=0 Connected to 2c:59:17:00:42:27 (on wl2) SSID: testpilot2G freq: 2412 RX: 448 bytes (2 packets) TX: 0 bytes (10 packets) signal: -26 dBm tx bitrate: 1.0 MBit/s bssid=2c:59:17:00:42:27 freq=2412 ssid=testpilot2G id=0 mode=station wifi_generation=6 pairwise_cipher=CCMP group_cipher=CCMP key_mgmt=SAE pmf=2 mgmt_group_cipher=BIP sae_group=19 sae_h2e=0 sae_pk=0 wpa_state=COMPLETED address=2c:59:17:00:19:a7 uuid=6d00ee6d-3672-579c-a38c-014d1a457cbc ]*\).*$/AssocMac24g=\1/p' AssocMac24g=2c:59:17:00:19:a7 DriverSmoothedRSSI24g=-18 ?" WiFi.AccessPoint.5.AssociatedDevice.1.AvgSignalStrength=0 | I11: Pass | J11: Pass | K11: Pass | L11: testpilot | N11: Pass | O11: Pass | P11: Pass
A12: WiFi.AccessPoint.{i}.AssociatedDevice.{i}. | B12: AssociatedDevice | C12: AvgSignalStrengthByChain | D12: ubus-cli WiFi.AccessPoint.{i}.AssociatedDevice.{i}.AvgSignalStrengthByChain=-41 | E12: Support | F12: pWHM
A13: WiFi.AccessPoint.{i}.AssociatedDevice.{i}. | B13: AssociatedDevice | C13: Capabilities | D13: ubus-cli WiFi.AccessPoint.{i}.AssociatedDevice.{i}.Capabilities=RRM,BTM,QOS_MAP | E13: Support | F13: pWHM
A14: WiFi.AccessPoint.{i}.AssociatedDevice.{i}. | B14: AssociatedDevice | C14: ChargeableUserId | D14: ubus-cli WiFi.AccessPoint.{i}.AssociatedDevice.{i}.ChargeableUserId= | E14: Support | F14: pWHM
A15: WiFi.AccessPoint.{i}.AssociatedDevice.{i}. | B15: AssociatedDevice | C15: ConnectionDuration | D15: ubus-cli WiFi.AccessPoint.{i}.AssociatedDevice.{i}.ConnectionDuration=8229 | E15: Support | F15: pWHM
A16: WiFi.AccessPoint.{i}.AssociatedDevice.{i}. | B16: AssociatedDevice | C16: DownlinkBandwidth | D16: ubus-cli WiFi.AccessPoint.{i}.AssociatedDevice.{i}.DownlinkBandwidth=0 | E16: Support | F16: pWHM
A17: WiFi.AccessPoint.{i}.AssociatedDevice.{i}. | B17: AssociatedDevice | C17: DownlinkMCS | D17: ubus-cli WiFi.AccessPoint.{i}.AssociatedDevice.{i}.DownlinkMCS=0 | E17: Support | F17: pWHM
A18: WiFi.AccessPoint.{i}.AssociatedDevice.{i}. | B18: AssociatedDevice | C18: DownlinkShortGuard | D18: ubus-cli WiFi.AccessPoint.{i}.AssociatedDevice.{i}.DownlinkShortGuard=0 | E18: Support | F18: pWHM
A19: WiFi.AccessPoint.{i}.AssociatedDevice.{i}. | B19: AssociatedDevice | C19: EncryptionMode | D19: ubus-cli WiFi.AccessPoint.{i}.AssociatedDevice.{i}.EncryptionMode=AES | E19: Support | F19: pWHM
A20: WiFi.AccessPoint.{i}.AssociatedDevice.{i}. | B20: AssociatedDevice | C20: FrequencyCapabilities | D20: ubus-cli WiFi.AccessPoint.{i}.AssociatedDevice.{i}.FrequencyCapabilities= | E20: Support | F20: pWHM
A21: WiFi.AccessPoint.{i}.AssociatedDevice.{i}. | B21: AssociatedDevice | C21: HeCapabilities | D21: ubus-cli WiFi.AccessPoint.{i}.AssociatedDevice.{i}.HeCapabilities= | E21: Support | F21: pWHM
A22: WiFi.AccessPoint.{i}.AssociatedDevice.{i}. | B22: AssociatedDevice | C22: HtCapabilities | D22: ubus-cli WiFi.AccessPoint.{i}.AssociatedDevice.{i}.HtCapabilities=40MHz,SGI20,SGI40 | E22: Support | F22: pWHM
A23: WiFi.AccessPoint.{i}.AssociatedDevice.{i}. | B23: AssociatedDevice | C23: Inactive | D23: ubus-cli WiFi.AccessPoint.{i}.AssociatedDevice.{i}.Inactive=0 | E23: Support | F23: pWHM
... A251: WiFi.Radio.{i}.Vendor. | B251: Radio | C251: RegulatoryDomain | D251: ubus-cli WiFi.Radio.{i}.Vendor.Brcm.RegulatoryDomainRev=0 | E251: Support | F251: Vendor Module
A252: WiFi.Radio.{i}.Vendor. | B252: Radio | D252: ubus-cli WiFi.Radio.{i}.Vendor.Brcm.RegulatoryDomainSupported? | E252: Not Supported | F252: Not Support | I252: Not Support | J252: Not Support | K252: Not Support
A253: WiFi.Radio.{i}. | B253: Radio | C253: WDS_Mode | D253: ubus-cli WiFi.Radio.{i}.WDS_Mode=1 | E253: Not Supported | F253: Not Support
A254: WiFi.Radio.{i}. | B254: Radio | C254: getLatestPower() | D254: ubus-cli WiFi.Radio.{i}.getLatestPower():void | E254: Not Supported | F254: Not Support
A255: WiFi.Radio.{i}. | B255: Radio | C255: getPerAntennaRssi() | D255: ubus-cli WiFi.Radio.{i}.getPerAntennaRssi():void | E255: Not Supported | F255: Not Support
A256: WiFi.Radio.{i}. | B256: Radio | C256: getRadioAirStats() | D256: ubus-cli WiFi.Radio.{i}.getRadioAirStats() FreeTime : 89, | E256: Support | F256: pWHM
A257: WiFi.Radio.{i}. | B257: Radio | C257: getRadioAirStats() | D257: ubus-cli WiFi.Radio.{i}.getRadioAirStats() Load : 12, | E257: Support | F257: pWHM
A258: WiFi.Radio.{i}. | B258: Radio | C258: getRadioAirStats() | D258: ubus-cli WiFi.Radio.{i}.getRadioAirStats() Noise : -92, | E258: Support | F258: pWHM
A259: WiFi.Radio.{i}. | B259: Radio | C259: getRadioAirStats() | D259: ubus-cli WiFi.Radio.{i}.getRadioAirStats() RxTime : 0, | E259: Support | F259: pWHM
A260: WiFi.Radio.{i}. | B260: Radio | C260: getRadioAirStats() | D260: ubus-cli WiFi.Radio.{i}.getRadioAirStats() TotalTime : 102, | E260: Support | F260: pWHM
A261: WiFi.Radio.{i}. | B261: Radio | C261: getRadioAirStats() | D261: ubus-cli WiFi.Radio.{i}.getRadioAirStats() TxTime : 4, | E261: Support | F261: pWHM
A262: WiFi.Radio.{i}. | B262: Radio | C262: getRadioAirStats() | D262: ubus-cli WiFi.Radio.{i}.getRadioAirStats():void | E262: Support | F262: pWHM
A263: WiFi.Radio.{i}. | B263: Statistics | C263: getRadioStats() | D263: ubus-cli WiFi.Radio.{i}.getRadioStats()BroadcastPacketsReceived : 0, | E263: Support | F263: Vendor Module
A264: WiFi.Radio.{i}. | B264: Statistics | C264: getRadioStats() | D264: ubus-cli WiFi.Radio.{i}.getRadioStats()BroadcastPacketsSent : 0, | E264: Support | F264: Vendor Module
... A746: WiFi.Radio.{i}.80211be. | B746: Wi-Fi 7 | C746: EMLSREnable | D746: ubus-cli WiFi.Radio.{i}.​80211be.EMLSREnable | E746: Not Supported | F746: Not Support
I750: =COUNTIF(I2:I744,"*PASS*") | J750: =COUNTIF(J2:J744,"*PASS*") | K750: =COUNTIF(K2:K744,"*PASS*")
I751: =COUNTIF(I2:I744,"*Failed*") | J751: =COUNTIF(J2:J745,"*Failed*") | K751: =COUNTIF(K2:K745,"*Failed*")
...

Sheet _meta
A1: run_date | B1: 2026-07-01
A2: dut_fw_ver | B2: bed6dab1-SAE-issue11-recheck
A3: source_excel
A4: sheet_name | B4: Wifi_LLAPI
